Traceback (most recent call last):
  File "./experiments/CPSO-NUMPY/main.py", line 10, in <module>
    import matplotlib.pyplot as plt
  File "/home/student/rh18vo/.local/lib/python3.8/site-packages/matplotlib/pyplot.py", line 57, in <module>
    from matplotlib.figure import Figure, figaspect
  File "/home/student/rh18vo/.local/lib/python3.8/site-packages/matplotlib/figure.py", line 25, in <module>
    from matplotlib import _blocking_input, docstring, projections
  File "/home/student/rh18vo/.local/lib/python3.8/site-packages/matplotlib/projections/__init__.py", line 55, in <module>
    from .. import axes, docstring
  File "/home/student/rh18vo/.local/lib/python3.8/site-packages/matplotlib/axes/__init__.py", line 1, in <module>
    from ._subplots import *
  File "/home/student/rh18vo/.local/lib/python3.8/site-packages/matplotlib/axes/_subplots.py", line 3, in <module>
    from matplotlib.axes._axes import Axes
  File "/home/student/rh18vo/.local/lib/python3.8/site-packages/matplotlib/axes/_axes.py", line 10, in <module>
    import matplotlib.category  # Register category unit converter as side-effect.
  File "/home/student/rh18vo/.local/lib/python3.8/site-packages/matplotlib/category.py", line 14, in <module>
    import dateutil.parser
  File "/home/student/rh18vo/.local/lib/python3.8/site-packages/dateutil/parser/__init__.py", line 2, in <module>
    from ._parser import parse, parser, parserinfo, ParserError
  File "/home/student/rh18vo/.local/lib/python3.8/site-packages/dateutil/parser/_parser.py", line 42, in <module>
    import six
ModuleNotFoundError: No module named 'six'
